Workbook

Sheet CC 2023
E2: Employee Name | L2: =CONCATENATE(G146,"/",Q174) -> #DIV/0!
E3: 2023
E4: Part 1: Ice Breaker : Introduction & General Feedback
E6: Role:
E7: Reports to:
E8: Start Date:
E10: Mid-year meeting
E11: End-of-year meeting
E14: How do you feel? Any ideas for BWD to improve ? | G14: ='CC 2023'!E2 -> Employee Name | L14: out of 10
E15: =CONCATENATE("Mid-year meeting - ", TEXT($F$10,"dd/mm/yyyy")) -> Mid-year meeting - 00/01/1900 | F15: What is going well in my role
F16: What is challenging in my role
F17: How is BWD as an Employer ( management style, culture, work environment)
F18: Average | G18: =AVERAGE(L15:L17) -> #DIV/0!
E19: =CONCATENATE("End-of-year meeting - ", TEXT($F$11,"dd/mm/yyyy")) -> End-of-year meeting - 00/01/1900 | F19: What is going well
F20: What is challenging
F21: How is BWD as an Employer ( management style, culture, work environment)
F22: Average | G22: =AVERAGE(L19:L21) -> #DIV/0!
E25: Part 2: Your skill set & Learning Plan
E26: Just checking your current skill-set and exploring new competences to develop.
E28: SKILL 1
E29: =CONCATENATE("Mid-year meeting - ", TEXT($F$10,"dd/mm/yyyy")) -> Mid-year meeting - 00/01/1900 | G29: ='CC 2023'!E2 -> Employee Name | J29: =F7 -> 0
E31: =CONCATENATE("End-of-year meeting - ", TEXT($F$11,"dd/mm/yyyy")) -> End-of-year meeting - 00/01/1900 | G31: ='CC 2023'!E2 -> Employee Name | J31: =F7 -> 0
E34: SKILL 2
E35: =CONCATENATE("Mid-year meeting - ", TEXT($F$10,"dd/mm/yyyy")) -> Mid-year meeting - 00/01/1900 | G35: ='CC 2023'!E2 -> Employee Name | J35: =F7 -> 0
E37: =CONCATENATE("End-of-year meeting - ", TEXT($F$11,"dd/mm/yyyy")) -> End-of-year meeting - 00/01/1900 | G37: ='CC 2023'!E2 -> Employee Name | J37: =F7 -> 0
E40: SKILL 3
E41: =CONCATENATE("Mid-year meeting - ", TEXT($F$10,"dd/mm/yyyy")) -> Mid-year meeting - 00/01/1900 | G41: ='CC 2023'!E2 -> Employee Name | J41: =F7 -> 0
E43: =CONCATENATE("End-of-year meeting - ", TEXT($F$11,"dd/mm/yyyy")) -> End-of-year meeting - 00/01/1900 | G43: ='CC 2023'!E2 -> Employee Name | J43: =F7 -> 0
E46: SKILL 4
E47: =CONCATENATE("Mid-year meeting - ", TEXT($F$10,"dd/mm/yyyy")) -> Mid-year meeting - 00/01/1900 | G47: ='CC 2023'!E2 -> Employee Name | J47: =F7 -> 0
E49: =CONCATENATE("End-of-year meeting - ", TEXT($F$11,"dd/mm/yyyy")) -> End-of-year meeting - 00/01/1900 | G49: ='CC 2023'!E2 -> Employee Name | J49: =F7 -> 0
E52: SKILL 5
E53: =CONCATENATE("Mid-year meeting - ", TEXT($F$10,"dd/mm/yyyy")) -> Mid-year meeting - 00/01/1900 | G53: ='CC 2023'!E2 -> Employee Name | J53: =F7 -> 0
E55: =CONCATENATE("End-of-year meeting - ", TEXT($F$11,"dd/mm/yyyy")) -> End-of-year meeting - 00/01/1900 | G55: ='CC 2023'!E2 -> Employee Name | J55: =F7 -> 0
E58: SKILL 6
E59: =CONCATENATE("Mid-year meeting - ", TEXT($F$10,"dd/mm/yyyy")) -> Mid-year meeting - 00/01/1900 | G59: ='CC 2023'!E2 -> Employee Name | J59: =F7 -> 0
E61: =CONCATENATE("End-of-year meeting - ", TEXT($F$11,"dd/mm/yyyy")) -> End-of-year meeting - 00/01/1900 | G61: ='CC 2023'!E2 -> Employee Name | J61: =F7 -> 0
E64: SKILL 7
E65: =CONCATENATE("Mid-year meeting - ", TEXT($F$10,"dd/mm/yyyy")) -> Mid-year meeting - 00/01/1900 | G65: ='CC 2023'!E2 -> Employee Name | J65: =F7 -> 0
E67: =CONCATENATE("End-of-year meeting - ", TEXT($F$11,"dd/mm/yyyy")) -> End-of-year meeting - 00/01/1900 | G67: ='CC 2023'!E2 -> Employee Name | J67: =F7 -> 0
...

Sheet Ramp Up Model
D2: ='CC 2023'!E2 -> Employee Name | K2: =CONCATENATE($L$231,$K$193) -> #VALUE!
D4: Part 1 : Ice Breaker : Introduction & General Feedback
D5: New Role | E5: Full Stack Developer
D6: Reports to | E6: Anael
D7: Context | E7: Akshat Replacement - Akshat last day of work if 1/5/2024
D10: Job Description* | E10: As the Full Stack Developer, you will report to the Director - Engineering and IT and play a critical role in designing, developing, deploying, maintaining, and supporting our diverse range of applications. Your efforts will be closely aligned with our IT strategy and product roadmap, ensuring our technological solutions remain at the forefront of industry standards. Key tasks and responsibilities Participate in strategic decision-making and contribute to the design of the 2023 Roadmap Report to the manager on collaboration and projects, and proactively offer solutions Participate in designing and implementing the software architecture and applications Review, identify, propose, and implement changes in our current application stacks, in collaboration with IT system team, to optimize costs and reduce maintenance In accordance with company cybersecurity roadmap and industry best practices, adapt, improve and update internal applications to be compliant with written policies. ldentify, test, recommend, develop and deploy applications and tools including and not limited to Java related technologies and frameworks that are relevant to the business requirements of the company. ldentify, assess, advise on, develop and implement centralized software development tools and development guidelines and processes that are the state of the art in implementing front-end and back-end applications Maintain updated overview of the software stack and applications, their interactions and user documentations Participate in and facilitate code reviews with peers
E13: 2023 KPIs | J13: 1
E14: COMPANY PERFORMANCE | J14: 0.3
E15: 2023 Order Intake
E16: 2023 Cost Management
E17: 2023 Return on Capital Employed
E18: TEAM GOALS* | J18: 0.2
E23: SMART GOALS* | J23: 0.3
E28: COMPANY VALUES AMBASSADOR | J28: 0.2
E29: Quality
E30: Innovation
E31: Collaboration
E32: Customer centricity
E36: Start date | I36: 45329
E37: Meeting 1 (during 1st week) | I37: 15/02/2024
E38: Meeting 2 | I38: 45369
E39: Meeting 3 | I39: 15/04/2024
D41: Part 1: Introduction & General Feedback
D42: How do you feel? Any ideas for BWD to improve ? | F42: Team member | J42: Manager
D43: =CONCATENATE("Meeting 1 - ", TEXT(I37,"dd/mm/yyyy")) -> Meeting 1 - 15/02/2024 | E43: What is going well in my role | F43: Things are going well, have everything he needs, will request more services and accesses later on. | I43: 8 | J43: Akshat : confirms he will give access later. Good 1st week - Anael : MCP should be available. Good 1st success with a alarm problem solved. He has a lot to discover.
E44: What is challenging in my role | F44: get familiar to tools
E45: How is BWD as an Employer ( management style, culture, work environment) | F45: Nice people, good environment , quite relax, efficiency | I45: 9 | J45: Marie encourages to catchup with Thasa and Graham
E46: Average | F46: =AVERAGE(I43:I45) -> 8.5
D47: =CONCATENATE("Meeting 2 - ", TEXT(I38,"dd/mm/yyyy")) -> Meeting 2 - 18/03/2024 | E47: What is going well in my role | F47: Transfer is shared session by session, with practical opportunity in between | I47: 9 | J47: exceptional job since last month , Oscar is almost autonomous / confirmed bby Anael, ex Pat dashboard
E48: What is challenging in my role | F48: some apps are complex and require more time : NRMS > need more practice | J48: there will be more session and work on NRMS
E49: How is BWD as an Employer ( management style, culture, work environment) | F49: people are still nice and helpful | I49: 9
E50: Average | F50: =AVERAGE(I47:I49) -> 9
D51: =CONCATENATE("Meeting 3 - ", TEXT(I39,"dd/mm/yyyy")) -> Meeting 3 - 15/04/2024 | E51: What is going well in my role | I51: 0
E52: What is challenging in my role
E53: How is BWD as an Employer ( management style, culture, work environment)
E54: Average | F54: =AVERAGE(I51:I53) -> 0
D58: Part 2: Skills Audit and Upskilling Plan
D59: Let's check how comfortable you feel for each main component of your new role. Identify any gaps and create an upskilling plan to help you become an expert. This plan will involve formal training and learning by doing. Monitor the progression with your % of autonomy.
D61: SKILL 1* | F61: Technology – Spring Boot, Java , MySQL , Graph DB , Docker, Groovy, Node.js , Angular , SQL, Unix , shell scripts
D62: =CONCATENATE("Meeting 1 - ", TEXT($I$37,"dd/mm/yyyy")) -> Meeting 1 - 15/02/2024 | G62: Team member | I62: Manager*
...

Sheet CC 2024
E2: ='CC 2023'!E2 -> Employee Name | L2: =CONCATENATE(G146,"/",Q174) -> #DIV/0!
E3: 2023
E4: Part 1: Ice Breaker : Introduction & General Feedback
E6: Role: | F6: Full Stack Developer
E7: Reports to: | F7: Anael
E8: Start Date: | F8: 45475
E10: Mid-year meeting
E11: End-of-year meeting
E14: How do you feel? Any ideas for BWD to improve ? | G14: ='CC 2023'!E2 -> Employee Name | L14: out of 10
E15: =CONCATENATE("Mid-year meeting - ", TEXT($F$10,"dd/mm/yyyy")) -> Mid-year meeting - 00/01/1900 | F15: What is going well in my role
F16: What is challenging in my role
F17: How is BWD as an Employer ( management style, culture, work environment)
F18: Average | G18: =AVERAGE(L15:L17) -> #DIV/0!
E19: =CONCATENATE("End-of-year meeting - ", TEXT($F$11,"dd/mm/yyyy")) -> End-of-year meeting - 00/01/1900 | F19: What is going well
F20: What is challenging
F21: How is BWD as an Employer ( management style, culture, work environment)
F22: Average | G22: =AVERAGE(L19:L21) -> #DIV/0!
E25: Part 2: Your skill set & Learning Plan
E26: Just checking your current skill-set and exploring new competences to develop.
E28: SKILL 1 | F28: Technology – Spring Boot, Java , MySQL , Graph DB , Docker, Groovy, Node.js , Angular , SQL, Unix , shell scripts
E29: =CONCATENATE("Mid-year meeting - ", TEXT($F$10,"dd/mm/yyyy")) -> Mid-year meeting - 00/01/1900 | G29: ='CC 2023'!E2 -> Employee Name | J29: =F7 -> Anael
E31: =CONCATENATE("End-of-year meeting - ", TEXT($F$11,"dd/mm/yyyy")) -> End-of-year meeting - 00/01/1900 | G31: ='CC 2023'!E2 -> Employee Name | J31: =F7 -> Anael
E34: SKILL 2 | F34: Tools - Grafana, GitLab, Jenkins , Confluence , OTRS , JIRA, OpenNMS , MariaDb , Postgres DB
E35: =CONCATENATE("Mid-year meeting - ", TEXT($F$10,"dd/mm/yyyy")) -> Mid-year meeting - 00/01/1900 | G35: ='CC 2023'!E2 -> Employee Name | J35: =F7 -> Anael
E37: =CONCATENATE("End-of-year meeting - ", TEXT($F$11,"dd/mm/yyyy")) -> End-of-year meeting - 00/01/1900 | G37: ='CC 2023'!E2 -> Employee Name | J37: =F7 -> Anael
E40: SKILL 3 | F40: Integration – Pentahu
E41: =CONCATENATE("Mid-year meeting - ", TEXT($F$10,"dd/mm/yyyy")) -> Mid-year meeting - 00/01/1900 | G41: ='CC 2023'!E2 -> Employee Name | J41: =F7 -> Anael
E43: =CONCATENATE("End-of-year meeting - ", TEXT($F$11,"dd/mm/yyyy")) -> End-of-year meeting - 00/01/1900 | G43: ='CC 2023'!E2 -> Employee Name | J43: =F7 -> Anael
E46: SKILL 4
E47: =CONCATENATE("Mid-year meeting - ", TEXT($F$10,"dd/mm/yyyy")) -> Mid-year meeting - 00/01/1900 | G47: ='CC 2023'!E2 -> Employee Name | J47: =F7 -> Anael
E49: =CONCATENATE("End-of-year meeting - ", TEXT($F$11,"dd/mm/yyyy")) -> End-of-year meeting - 00/01/1900 | G49: ='CC 2023'!E2 -> Employee Name | J49: =F7 -> Anael
E52: SKILL 5
E53: =CONCATENATE("Mid-year meeting - ", TEXT($F$10,"dd/mm/yyyy")) -> Mid-year meeting - 00/01/1900 | G53: ='CC 2023'!E2 -> Employee Name | J53: =F7 -> Anael
E55: =CONCATENATE("End-of-year meeting - ", TEXT($F$11,"dd/mm/yyyy")) -> End-of-year meeting - 00/01/1900 | G55: ='CC 2023'!E2 -> Employee Name | J55: =F7 -> Anael
E58: SKILL 6
E59: =CONCATENATE("Mid-year meeting - ", TEXT($F$10,"dd/mm/yyyy")) -> Mid-year meeting - 00/01/1900 | G59: ='CC 2023'!E2 -> Employee Name | J59: =F7 -> Anael
E61: =CONCATENATE("End-of-year meeting - ", TEXT($F$11,"dd/mm/yyyy")) -> End-of-year meeting - 00/01/1900 | G61: ='CC 2023'!E2 -> Employee Name | J61: =F7 -> Anael
E64: SKILL 7
E65: =CONCATENATE("Mid-year meeting - ", TEXT($F$10,"dd/mm/yyyy")) -> Mid-year meeting - 00/01/1900 | G65: ='CC 2023'!E2 -> Employee Name | J65: =F7 -> Anael
E67: =CONCATENATE("End-of-year meeting - ", TEXT($F$11,"dd/mm/yyyy")) -> End-of-year meeting - 00/01/1900 | G67: ='CC 2023'!E2 -> Employee Name | J67: =F7 -> Anael
...

Sheet CC 2025
E2: ='CC 2023'!E2 -> Employee Name | L2: =CONCATENATE(G146,"/",Q174) -> #DIV/0!
E3: 2024
E4: Part 1: Ice Breaker : Introduction & General Feedback
E6: Role: | F6: ='CC 2024'!F6 -> Full Stack Developer
E7: Reports to: | F7: ='CC 2024'!F7 -> Anael
E8: Start Date: | F8: ='CC 2024'!F8 -> 45475
E10: Mid-year meeting | F10: TBD
E11: End-of-year meeting | F11: TBD
E14: How do you feel? Any ideas for BWD to improve ? | G14: ='CC 2023'!E2 -> Employee Name | L14: out of 10
E15: =CONCATENATE("Mid-year meeting - ", TEXT($F$10,"dd/mm/yyyy")) -> Mid-year meeting - TBD | F15: What is going well in my role
F16: What is challenging in my role
F17: How is BWD as an Employer ( management style, culture, work environment)
F18: Average | G18: =AVERAGE(L15:L17) -> #DIV/0!
E19: =CONCATENATE("End-of-year meeting - ", TEXT($F$11,"dd/mm/yyyy")) -> End-of-year meeting - TBD | F19: What is going well
F20: What is challenging
F21: How is BWD as an Employer ( management style, culture, work environment)
F22: Average | G22: =AVERAGE(L19:L21) -> #DIV/0!
E25: Part 2: Your skill set & Learning Plan
E26: Just checking your current skill-set and exploring new competences to develop.
E28: SKILL 1 | F28: ='CC 2024'!F28 -> Technology – Spring Boot, Java , MySQL , Graph DB , Docker, Groovy, Node.js , Angular , SQL, Unix , shell scripts
E29: =CONCATENATE("Mid-year meeting - ", TEXT($F$10,"dd/mm/yyyy")) -> Mid-year meeting - TBD | G29: ='CC 2023'!E2 -> Employee Name | J29: =F7 -> Anael
E31: =CONCATENATE("End-of-year meeting - ", TEXT($F$11,"dd/mm/yyyy")) -> End-of-year meeting - TBD | G31: ='CC 2023'!E2 -> Employee Name | J31: =F7 -> Anael
E34: SKILL 2 | F34: ='CC 2024'!F34 -> Tools - Grafana, GitLab, Jenkins , Confluence , OTRS , JIRA, OpenNMS , MariaDb , Postgres DB
E35: =CONCATENATE("Mid-year meeting - ", TEXT($F$10,"dd/mm/yyyy")) -> Mid-year meeting - TBD | G35: ='CC 2023'!E2 -> Employee Name | J35: =F7 -> Anael
E37: =CONCATENATE("End-of-year meeting - ", TEXT($F$11,"dd/mm/yyyy")) -> End-of-year meeting - TBD | G37: ='CC 2023'!E2 -> Employee Name | J37: =F7 -> Anael
E40: SKILL 3 | F40: ='CC 2024'!F40 -> Integration – Pentahu
E41: =CONCATENATE("Mid-year meeting - ", TEXT($F$10,"dd/mm/yyyy")) -> Mid-year meeting - TBD | G41: ='CC 2023'!E2 -> Employee Name | J41: =F7 -> Anael
E43: =CONCATENATE("End-of-year meeting - ", TEXT($F$11,"dd/mm/yyyy")) -> End-of-year meeting - TBD | G43: ='CC 2023'!E2 -> Employee Name | J43: =F7 -> Anael
E46: SKILL 4 | F46: ='CC 2024'!F46 -> 0
E47: =CONCATENATE("Mid-year meeting - ", TEXT($F$10,"dd/mm/yyyy")) -> Mid-year meeting - TBD | G47: ='CC 2023'!E2 -> Employee Name | J47: =F7 -> Anael
E49: =CONCATENATE("End-of-year meeting - ", TEXT($F$11,"dd/mm/yyyy")) -> End-of-year meeting - TBD | G49: ='CC 2023'!E2 -> Employee Name | J49: =F7 -> Anael
E52: SKILL 5 | F52: ='CC 2024'!F52 -> 0
E53: =CONCATENATE("Mid-year meeting - ", TEXT($F$10,"dd/mm/yyyy")) -> Mid-year meeting - TBD | G53: ='CC 2023'!E2 -> Employee Name | J53: =F7 -> Anael
E55: =CONCATENATE("End-of-year meeting - ", TEXT($F$11,"dd/mm/yyyy")) -> End-of-year meeting - TBD | G55: ='CC 2023'!E2 -> Employee Name | J55: =F7 -> Anael
E58: SKILL 6 | F58: ='CC 2024'!F58 -> 0
E59: =CONCATENATE("Mid-year meeting - ", TEXT($F$10,"dd/mm/yyyy")) -> Mid-year meeting - TBD | G59: ='CC 2023'!E2 -> Employee Name | J59: =F7 -> Anael
E61: =CONCATENATE("End-of-year meeting - ", TEXT($F$11,"dd/mm/yyyy")) -> End-of-year meeting - TBD | G61: ='CC 2023'!E2 -> Employee Name | J61: =F7 -> Anael
E64: SKILL 7 | F64: ='CC 2024'!F64 -> 0
E65: =CONCATENATE("Mid-year meeting - ", TEXT($F$10,"dd/mm/yyyy")) -> Mid-year meeting - TBD | G65: ='CC 2023'!E2 -> Employee Name | J65: =F7 -> Anael
E67: =CONCATENATE("End-of-year meeting - ", TEXT($F$11,"dd/mm/yyyy")) -> End-of-year meeting - TBD | G67: ='CC 2023'!E2 -> Employee Name | J67: =F7 -> Anael
...

Sheet CC 2026
E2: ='CC 2023'!E2 -> Employee Name | L2: =CONCATENATE(G146,"/",Q174) -> #DIV/0!
E3: 2025
E4: Part 1: Ice Breaker : Introduction & General Feedback
E6: Role: | F6: ='CC 2025'!F6 -> Full Stack Developer
E7: Reports to: | F7: ='CC 2025'!F7 -> Anael
E8: Start Date: | F8: ='CC 2025'!F8 -> 45475
E10: Mid-year meeting | F10: TBD
E11: End-of-year meeting | F11: TBD
E14: How do you feel? Any ideas for BWD to improve ? | G14: ='CC 2023'!E2 -> Employee Name | L14: out of 10
E15: =CONCATENATE("Mid-year meeting - ", TEXT($F$10,"dd/mm/yyyy")) -> Mid-year meeting - TBD | F15: What is going well in my role
F16: What is challenging in my role
F17: How is BWD as an Employer ( management style, culture, work environment)
F18: Average | G18: =AVERAGE(L15:L17) -> #DIV/0!
E19: =CONCATENATE("End-of-year meeting - ", TEXT($F$11,"dd/mm/yyyy")) -> End-of-year meeting - TBD | F19: What is going well
F20: What is challenging
F21: How is BWD as an Employer ( management style, culture, work environment)
F22: Average | G22: =AVERAGE(L19:L21) -> #DIV/0!
E25: Part 2: Your skill set & Learning Plan
E26: Just checking your current skill-set and exploring new competences to develop.
E28: SKILL 1 | F28: ='CC 2025'!F28 -> Technology – Spring Boot, Java , MySQL , Graph DB , Docker, Groovy, Node.js , Angular , SQL, Unix , shell scripts
E29: =CONCATENATE("Mid-year meeting - ", TEXT($F$10,"dd/mm/yyyy")) -> Mid-year meeting - TBD | G29: ='CC 2023'!E2 -> Employee Name | J29: =F7 -> Anael
E31: =CONCATENATE("End-of-year meeting - ", TEXT($F$11,"dd/mm/yyyy")) -> End-of-year meeting - TBD | G31: ='CC 2023'!E2 -> Employee Name | J31: =F7 -> Anael
E34: SKILL 2 | F34: ='CC 2025'!F34 -> Tools - Grafana, GitLab, Jenkins , Confluence , OTRS , JIRA, OpenNMS , MariaDb , Postgres DB
E35: =CONCATENATE("Mid-year meeting - ", TEXT($F$10,"dd/mm/yyyy")) -> Mid-year meeting - TBD | G35: ='CC 2023'!E2 -> Employee Name | J35: =F7 -> Anael
E37: =CONCATENATE("End-of-year meeting - ", TEXT($F$11,"dd/mm/yyyy")) -> End-of-year meeting - TBD | G37: ='CC 2023'!E2 -> Employee Name | J37: =F7 -> Anael
E40: SKILL 3 | F40: ='CC 2025'!F40 -> Integration – Pentahu
E41: =CONCATENATE("Mid-year meeting - ", TEXT($F$10,"dd/mm/yyyy")) -> Mid-year meeting - TBD | G41: ='CC 2023'!E2 -> Employee Name | J41: =F7 -> Anael
E43: =CONCATENATE("End-of-year meeting - ", TEXT($F$11,"dd/mm/yyyy")) -> End-of-year meeting - TBD | G43: ='CC 2023'!E2 -> Employee Name | J43: =F7 -> Anael
E46: SKILL 4 | F46: ='CC 2025'!F46 -> 0
E47: =CONCATENATE("Mid-year meeting - ", TEXT($F$10,"dd/mm/yyyy")) -> Mid-year meeting - TBD | G47: ='CC 2023'!E2 -> Employee Name | J47: =F7 -> Anael
E49: =CONCATENATE("End-of-year meeting - ", TEXT($F$11,"dd/mm/yyyy")) -> End-of-year meeting - TBD | G49: ='CC 2023'!E2 -> Employee Name | J49: =F7 -> Anael
E52: SKILL 5 | F52: ='CC 2025'!F52 -> 0
E53: =CONCATENATE("Mid-year meeting - ", TEXT($F$10,"dd/mm/yyyy")) -> Mid-year meeting - TBD | G53: ='CC 2023'!E2 -> Employee Name | J53: =F7 -> Anael
E55: =CONCATENATE("End-of-year meeting - ", TEXT($F$11,"dd/mm/yyyy")) -> End-of-year meeting - TBD | G55: ='CC 2023'!E2 -> Employee Name | J55: =F7 -> Anael
E58: SKILL 6 | F58: ='CC 2025'!F58 -> 0
E59: =CONCATENATE("Mid-year meeting - ", TEXT($F$10,"dd/mm/yyyy")) -> Mid-year meeting - TBD | G59: ='CC 2023'!E2 -> Employee Name | J59: =F7 -> Anael
E61: =CONCATENATE("End-of-year meeting - ", TEXT($F$11,"dd/mm/yyyy")) -> End-of-year meeting - TBD | G61: ='CC 2023'!E2 -> Employee Name | J61: =F7 -> Anael
E64: SKILL 7 | F64: ='CC 2025'!F64 -> 0
E65: =CONCATENATE("Mid-year meeting - ", TEXT($F$10,"dd/mm/yyyy")) -> Mid-year meeting - TBD | G65: ='CC 2023'!E2 -> Employee Name | J65: =F7 -> Anael
E67: =CONCATENATE("End-of-year meeting - ", TEXT($F$11,"dd/mm/yyyy")) -> End-of-year meeting - TBD | G67: ='CC 2023'!E2 -> Employee Name | J67: =F7 -> Anael
...

Sheet CC Model
E2: ='CC 2023'!E2 -> Employee Name | L2: =CONCATENATE(G146,"/",Q174) -> #DIV/0!
E3: 2023
E4: Part 1: Ice Breaker : Introduction & General Feedback
E6: Role:
E7: Reports to: | F7: Manager Name
E8: Start Date:
E10: Mid-year meeting | F10: TBD
E11: End-of-year meeting | F11: TBD
E14: How do you feel? Any ideas for BWD to improve ? | G14: ='CC 2023'!E2 -> Employee Name | L14: out of 10
E15: =CONCATENATE("Mid-year meeting - ", TEXT($F$10,"dd/mm/yyyy")) -> Mid-year meeting - TBD | F15: What is going well in my role
F16: What is challenging in my role
F17: How is BWD as an Employer ( management style, culture, work environment)
F18: Average | G18: =AVERAGE(L15:L17) -> #DIV/0!
E19: =CONCATENATE("End-of-year meeting - ", TEXT($F$11,"dd/mm/yyyy")) -> End-of-year meeting - TBD | F19: What is going well
F20: What is challenging
F21: How is BWD as an Employer ( management style, culture, work environment)
F22: Average | G22: =AVERAGE(L19:L21) -> #DIV/0!
E25: Part 2: Your skill set & Learning Plan
E26: Just checking your current skill-set and exploring new competences to develop.
E28: SKILL 1
E29: =CONCATENATE("Mid-year meeting - ", TEXT($F$10,"dd/mm/yyyy")) -> Mid-year meeting - TBD | G29: ='CC 2023'!E2 -> Employee Name | J29: =F7 -> Manager Name
E31: =CONCATENATE("End-of-year meeting - ", TEXT($F$11,"dd/mm/yyyy")) -> End-of-year meeting - TBD | G31: ='CC 2023'!E2 -> Employee Name | J31: =F7 -> Manager Name
E34: SKILL 2
E35: =CONCATENATE("Mid-year meeting - ", TEXT($F$10,"dd/mm/yyyy")) -> Mid-year meeting - TBD | G35: ='CC 2023'!E2 -> Employee Name | J35: =F7 -> Manager Name
E37: =CONCATENATE("End-of-year meeting - ", TEXT($F$11,"dd/mm/yyyy")) -> End-of-year meeting - TBD | G37: ='CC 2023'!E2 -> Employee Name | J37: =F7 -> Manager Name
E40: SKILL 3
E41: =CONCATENATE("Mid-year meeting - ", TEXT($F$10,"dd/mm/yyyy")) -> Mid-year meeting - TBD | G41: ='CC 2023'!E2 -> Employee Name | J41: =F7 -> Manager Name
E43: =CONCATENATE("End-of-year meeting - ", TEXT($F$11,"dd/mm/yyyy")) -> End-of-year meeting - TBD | G43: ='CC 2023'!E2 -> Employee Name | J43: =F7 -> Manager Name
E46: SKILL 4
E47: =CONCATENATE("Mid-year meeting - ", TEXT($F$10,"dd/mm/yyyy")) -> Mid-year meeting - TBD | G47: ='CC 2023'!E2 -> Employee Name | J47: =F7 -> Manager Name
E49: =CONCATENATE("End-of-year meeting - ", TEXT($F$11,"dd/mm/yyyy")) -> End-of-year meeting - TBD | G49: ='CC 2023'!E2 -> Employee Name | J49: =F7 -> Manager Name
E52: SKILL 5
E53: =CONCATENATE("Mid-year meeting - ", TEXT($F$10,"dd/mm/yyyy")) -> Mid-year meeting - TBD | G53: ='CC 2023'!E2 -> Employee Name | J53: =F7 -> Manager Name
E55: =CONCATENATE("End-of-year meeting - ", TEXT($F$11,"dd/mm/yyyy")) -> End-of-year meeting - TBD | G55: ='CC 2023'!E2 -> Employee Name | J55: =F7 -> Manager Name
E58: SKILL 6
E59: =CONCATENATE("Mid-year meeting - ", TEXT($F$10,"dd/mm/yyyy")) -> Mid-year meeting - TBD | G59: ='CC 2023'!E2 -> Employee Name | J59: =F7 -> Manager Name
E61: =CONCATENATE("End-of-year meeting - ", TEXT($F$11,"dd/mm/yyyy")) -> End-of-year meeting - TBD | G61: ='CC 2023'!E2 -> Employee Name | J61: =F7 -> Manager Name
E64: SKILL 7
E65: =CONCATENATE("Mid-year meeting - ", TEXT($F$10,"dd/mm/yyyy")) -> Mid-year meeting - TBD | G65: ='CC 2023'!E2 -> Employee Name | J65: =F7 -> Manager Name
E67: =CONCATENATE("End-of-year meeting - ", TEXT($F$11,"dd/mm/yyyy")) -> End-of-year meeting - TBD | G67: ='CC 2023'!E2 -> Employee Name | J67: =F7 -> Manager Name
...

Sheet CC 2027
E2: ='CC 2023'!E2 -> Employee Name | L2: =CONCATENATE(G146,"/",Q174) -> #DIV/0!
E3: 2026
E4: Part 1: Ice Breaker : Introduction & General Feedback
E6: Role: | F6: ='CC 2026'!F6 -> Full Stack Developer
E7: Reports to: | F7: ='CC 2026'!F7 -> Anael
E8: Start Date: | F8: ='CC 2026'!F8 -> 45475
E10: Mid-year meeting | F10: TBD
E11: End-of-year meeting | F11: TBD
E14: How do you feel? Any ideas for BWD to improve ? | G14: ='CC 2023'!E2 -> Employee Name | L14: out of 10
E15: =CONCATENATE("Mid-year meeting - ", TEXT($F$10,"dd/mm/yyyy")) -> Mid-year meeting - TBD | F15: What is going well in my role
F16: What is challenging in my role
F17: How is BWD as an Employer ( management style, culture, work environment)
F18: Average | G18: =AVERAGE(L15:L17) -> #DIV/0!
E19: =CONCATENATE("End-of-year meeting - ", TEXT($F$11,"dd/mm/yyyy")) -> End-of-year meeting - TBD | F19: What is going well
F20: What is challenging
F21: How is BWD as an Employer ( management style, culture, work environment)
F22: Average | G22: =AVERAGE(L19:L21) -> #DIV/0!
E25: Part 2: Your skill set & Learning Plan
E26: Just checking your current skill-set and exploring new competences to develop.
E28: SKILL 1 | F28: ='CC 2026'!F28 -> Technology – Spring Boot, Java , MySQL , Graph DB , Docker, Groovy, Node.js , Angular , SQL, Unix , shell scripts
E29: =CONCATENATE("Mid-year meeting - ", TEXT($F$10,"dd/mm/yyyy")) -> Mid-year meeting - TBD | G29: ='CC 2023'!E2 -> Employee Name | J29: =F7 -> Anael
E31: =CONCATENATE("End-of-year meeting - ", TEXT($F$11,"dd/mm/yyyy")) -> End-of-year meeting - TBD | G31: ='CC 2023'!E2 -> Employee Name | J31: =F7 -> Anael
E34: SKILL 2 | F34: ='CC 2026'!F34 -> Tools - Grafana, GitLab, Jenkins , Confluence , OTRS , JIRA, OpenNMS , MariaDb , Postgres DB
E35: =CONCATENATE("Mid-year meeting - ", TEXT($F$10,"dd/mm/yyyy")) -> Mid-year meeting - TBD | G35: ='CC 2023'!E2 -> Employee Name | J35: =F7 -> Anael
E37: =CONCATENATE("End-of-year meeting - ", TEXT($F$11,"dd/mm/yyyy")) -> End-of-year meeting - TBD | G37: ='CC 2023'!E2 -> Employee Name | J37: =F7 -> Anael
E40: SKILL 3 | F40: ='CC 2026'!F40 -> Integration – Pentahu
E41: =CONCATENATE("Mid-year meeting - ", TEXT($F$10,"dd/mm/yyyy")) -> Mid-year meeting - TBD | G41: ='CC 2023'!E2 -> Employee Name | J41: =F7 -> Anael
E43: =CONCATENATE("End-of-year meeting - ", TEXT($F$11,"dd/mm/yyyy")) -> End-of-year meeting - TBD | G43: ='CC 2023'!E2 -> Employee Name | J43: =F7 -> Anael
E46: SKILL 4 | F46: ='CC 2026'!F46 -> 0
E47: =CONCATENATE("Mid-year meeting - ", TEXT($F$10,"dd/mm/yyyy")) -> Mid-year meeting - TBD | G47: ='CC 2023'!E2 -> Employee Name | J47: =F7 -> Anael
E49: =CONCATENATE("End-of-year meeting - ", TEXT($F$11,"dd/mm/yyyy")) -> End-of-year meeting - TBD | G49: ='CC 2023'!E2 -> Employee Name | J49: =F7 -> Anael
E52: SKILL 5 | F52: ='CC 2026'!F52 -> 0
E53: =CONCATENATE("Mid-year meeting - ", TEXT($F$10,"dd/mm/yyyy")) -> Mid-year meeting - TBD | G53: ='CC 2023'!E2 -> Employee Name | J53: =F7 -> Anael
E55: =CONCATENATE("End-of-year meeting - ", TEXT($F$11,"dd/mm/yyyy")) -> End-of-year meeting - TBD | G55: ='CC 2023'!E2 -> Employee Name | J55: =F7 -> Anael
E58: SKILL 6 | F58: ='CC 2026'!F58 -> 0
E59: =CONCATENATE("Mid-year meeting - ", TEXT($F$10,"dd/mm/yyyy")) -> Mid-year meeting - TBD | G59: ='CC 2023'!E2 -> Employee Name | J59: =F7 -> Anael
E61: =CONCATENATE("End-of-year meeting - ", TEXT($F$11,"dd/mm/yyyy")) -> End-of-year meeting - TBD | G61: ='CC 2023'!E2 -> Employee Name | J61: =F7 -> Anael
E64: SKILL 7 | F64: ='CC 2026'!F64 -> 0
E65: =CONCATENATE("Mid-year meeting - ", TEXT($F$10,"dd/mm/yyyy")) -> Mid-year meeting - TBD | G65: ='CC 2023'!E2 -> Employee Name | J65: =F7 -> Anael
E67: =CONCATENATE("End-of-year meeting - ", TEXT($F$11,"dd/mm/yyyy")) -> End-of-year meeting - TBD | G67: ='CC 2023'!E2 -> Employee Name | J67: =F7 -> Anael
...

Sheet Dashboard
A1: =TODAY() -> 45443
C5: Dashboard - Career Conversations
C6: Note: Some rows for future years are hidden. Unhide them when needed.
C7: ='CC 2023'!E2 -> Employee Name
C8: =YEAR(A1) -> 2024
D9: Our Vision | E9: We connect countries across oceans sustainably
D10: Our Mission | E10: We develop, fund and operate digital infrastructures in the Asia-Pacific region
D11: Our Values | E11: Quality, Innovation, Collaboration, Customer centricity
D13: My Mission What is your very own purpose?
D16: Start - Stop - Continue
D18: Date | E18: Start | F18: Stop | G18: Continue
D19: 2023 | E19: =CONCATENATE('CC 2023'!$F$187, " | ", 'CC 2023'!$F$188) -> | | F19: =CONCATENATE('CC 2023'!$H$187, " | ", 'CC 2023'!$H$188) -> | | G19: =CONCATENATE('CC 2023'!$K$187, " | ", 'CC 2023'!$K$188) -> |
D20: 2024 | E20: =CONCATENATE('CC 2024'!$F$187, " | ", 'CC 2024'!$F$188) -> | | F20: =CONCATENATE('CC 2024'!$H$187, " | ", 'CC 2024'!$H$188) -> | | G20: =CONCATENATE('CC 2024'!$K$187, " | ", 'CC 2024'!$K$188) -> |
D21: 2025 | E21: =CONCATENATE('CC 2025'!$F$187, " | ", 'CC 2025'!$F$188) -> | | F21: =CONCATENATE('CC 2025'!$H$187, " | ", 'CC 2025'!$H$188) -> | | G21: =CONCATENATE('CC 2025'!$K$187, " | ", 'CC 2025'!$K$188) -> |
D22: 2026 | E22: =CONCATENATE('CC 2026'!$F$187, " | ", 'CC 2026'!$F$188) -> | | F22: =CONCATENATE('CC 2026'!$H$187, " | ", 'CC 2026'!$H$188) -> | | G22: =CONCATENATE('CC 2026'!$K$187, " | ", 'CC 2026'!$K$188) -> |
D23: 2027 | E23: =CONCATENATE('CC 2027'!$F$187, " | ", 'CC 2027'!$F$188) -> | | F23: =CONCATENATE('CC 2027'!$H$187, " | ", 'CC 2027'!$H$188) -> | | G23: =CONCATENATE('CC 2027'!$K$187, " | ", 'CC 2027'!$K$188) -> |
D27: SMART Goals
D29: Date | E29: Description | F29: Team member status | G29: Manager status
D30: 2023 | E30: ='CC 2023'!$F$87 -> Talent Acquisition ( 100% fast & successful recruitments ) 2023 | F30: =MAX('CC 2023'!$F$92:$G$93) -> 0 | G30: =MAX('CC 2023'!$F$96:$G$97) -> 0
D31: 2023 | E31: ='CC 2023'!$F$99 -> 0 | F31: =MAX('CC 2023'!$F$104:$G$105) -> 0 | G31: =MAX('CC 2023'!$F$108:$G$109) -> 0
D32: 2023 | E32: ='CC 2023'!$F111 -> 0 | F32: =MAX('CC 2023'!$F$116:$G$117) -> 0 | G32: =MAX('CC 2023'!$F$120:$G$121) -> 0
D33: 2023 | E33: ='CC 2023'!$F$123 -> 0 | F33: =MAX('CC 2023'!$F$128:$G$129) -> 0 | G33: =MAX('CC 2023'!$F$132:$G$133) -> 0
D34: 2023 | E34: ='CC 2023'!$F$135 -> 0 | F34: =MAX('CC 2023'!$F$140:$G$141) -> 0 | G34: =MAX('CC 2023'!$F$144:$G$145) -> 0
D35: 2024 | F35: =MAX('CC 2024'!$F$92:$G$93) -> 0 | G35: =MAX('CC 2024'!$F$96:$G$97) -> 0
D36: 2024 | E36: ='CC 2024'!$F$99 -> Improve NRMS usability | F36: =MAX('CC 2024'!$F$104:$G$105) -> 0 | G36: =MAX('CC 2024'!$F$108:$G$109) -> 0
D37: 2024 | E37: ='CC 2024'!$F116 -> 0 | F37: =MAX('CC 2024'!$F$116:$G$117) -> 0 | G37: =MAX('CC 2024'!$F$120:$G$121) -> 0
D38: 2024 | E38: ='CC 2024'!$F$123 -> Investigate how a chatbot / AI can help NOC operations | F38: =MAX('CC 2024'!$F$128:$G$129) -> 0 | G38: =MAX('CC 2024'!$F$132:$G$133) -> 0
D39: 2024 | E39: ='CC 2024'!$F$135 -> Deliver on User Requests | F39: =MAX('CC 2024'!$F$140:$G$141) -> 0 | G39: =MAX('CC 2024'!$F$144:$G$145) -> 0
D40: 2025 | E40: ='CC 2025'!$F$87 -> Support container architecture | F40: =MAX('CC 2025'!$F$92:$G$93) -> 0 | G40: =MAX('CC 2025'!$F$96:$G$97) -> 0
D41: 2025 | E41: ='CC 2025'!$F$99 -> Improve NRMS usability | F41: =MAX('CC 2025'!$F$104:$G$105) -> 0 | G41: =MAX('CC 2025'!$F$108:$G$109) -> 0
D42: 2025 | E42: ='CC 2025'!$F121 -> 0 | F42: =MAX('CC 2025'!$F$116:$G$117) -> 0 | G42: =MAX('CC 2025'!$F$120:$G$121) -> 0
D43: 2025 | E43: ='CC 2025'!$F$123 -> Investigate how a chatbot / AI can help NOC operations | F43: =MAX('CC 2025'!$F$128:$G$129) -> 0 | G43: =MAX('CC 2025'!$F$132:$G$133) -> 0
D44: 2025 | E44: ='CC 2025'!$F$135 -> Deliver on User Requests | F44: =MAX('CC 2025'!$F$140:$G$141) -> 0 | G44: =MAX('CC 2025'!$F$144:$G$145) -> 0
D45: 2026 | E45: ='CC 2026'!$F$87 -> Support container architecture | F45: =MAX('CC 2026'!$F$92:$G$93) -> 0 | G45: =MAX('CC 2026'!$F$96:$G$97) -> 0
D46: 2026 | E46: ='CC 2026'!$F$99 -> Improve NRMS usability | F46: =MAX('CC 2026'!$F$104:$G$105) -> 0 | G46: =MAX('CC 2026'!$F$108:$G$109) -> 0
D47: 2026 | E47: ='CC 2026'!$F126 -> Employee Name | F47: =MAX('CC 2026'!$F$116:$G$117) -> 0 | G47: =MAX('CC 2026'!$F$120:$G$121) -> 0
D48: 2026 | E48: ='CC 2026'!$F$123 -> Investigate how a chatbot / AI can help NOC operations | F48: =MAX('CC 2026'!$F$128:$G$129) -> 0 | G48: =MAX('CC 2026'!$F$132:$G$133) -> 0
D49: 2026 | E49: ='CC 2026'!$F$135 -> Deliver on User Requests | F49: =MAX('CC 2026'!$F$140:$G$141) -> 0 | G49: =MAX('CC 2026'!$F$144:$G$145) -> 0
D50: 2027 | E50: ='CC 2027'!$F$87 -> 0 | F50: =MAX('CC 2027'!$F$92:$G$93) -> 0 | G50: =MAX('CC 2027'!$F$96:$G$97) -> 0
D51: 2027 | E51: ='CC 2027'!$F$99 -> 0 | F51: =MAX('CC 2027'!$F$104:$G$105) -> 0 | G51: =MAX('CC 2027'!$F$108:$G$109) -> 0
...
